<?xml version="1.0"?>
<robot name="mecanum_bot" xmlns:xacro="http://www.ros.org/wiki/xacro">

  <!-- Define Colors -->
  <material name="white">
    <color rgba="1 1 1 1"/>
  </material>
  <material name="black">
    <color rgba="0 0 0 1"/>
  </material>

  <!-- Dummy Root Link -->
  <link name="world"/>

  <!-- Base Link -->
  <link name="base_link">
    <inertial>
      <mass value="5.0"/>
      <origin xyz="0 0 0"/>
      <inertia ixx="0.1" ixy="0.0" ixz="0.0" iyy="0.1" iyz="0.0" izz="0.1"/>
    </inertial>
    <visual>
      <geometry>
        <box size="0.295 0.145 0.05"/>
      </geometry>
      <material name="white"/>
    </visual>
    <collision>
      <geometry>
        <box size="0.295 0.145 0.05"/>
      </geometry>
    </collision>
  </link>

  <!-- Attach base_link to dummy root link -->
  <joint name="world_to_base" type="fixed">
    <parent link="world"/>
    <child link="base_link"/>
    <origin xyz="0 0 0" rpy="0 0 0"/>
  </joint>

  <!-- Wheels -->
  <xacro:macro name="wheel" params="name x y z">
    <link name="${name}">
      <visual>
        <geometry>
          <cylinder length="0.05" radius="0.05"/>
        </geometry>
        <material name="black"/>
      </visual>
      <collision>
        <geometry>
          <cylinder length="0.05" radius="0.05"/>
        </geometry>
      </collision>
    </link>
    <joint name="${name}_joint" type="continuous">
      <parent link="base_link"/>
      <child link="${name}"/>
      <origin xyz="${x} ${y} ${z}" rpy="0 0 0"/>
      <axis xyz="0 1 0"/>
    </joint>
  </xacro:macro>

  <xacro:wheel name="front_left_wheel" x="0.1475" y="0.0725" z="-0.05"/>
  <xacro:wheel name="front_right_wheel" x="0.1475" y="-0.0725" z="-0.05"/>
  <xacro:wheel name="rear_left_wheel" x="-0.1475" y="0.0725" z="-0.05"/>
  <xacro:wheel name="rear_right_wheel" x="-0.1475" y="-0.0725" z="-0.05"/>

  <!-- Lidar Mount -->
  <link name="lidar_mount">
    <visual>
      <geometry>
        <cylinder length="0.05" radius="0.04"/>
      </geometry>
      <material name="black"/>
    </visual>
  </link>
  <joint name="lidar_joint" type="fixed">
    <parent link="base_link"/>
    <child link="lidar_mount"/>
    <origin xyz="0 0 0.1" rpy="0 0 0"/>
  </joint>

  <!-- ROS2 Control Interface -->
  <ros2_control name="MecanumRobot" type="system">
      <hardware>
          <plugin>mecanum_hardware_interface/MecanumHardware</plugin>
      </hardware>
      <joint name="front_left_wheel_joint">
          <command_interface name="velocity"/>
          <state_interface name="velocity"/>
      </joint>
      <joint name="front_right_wheel_joint">
          <command_interface name="velocity"/>
          <state_interface name="velocity"/>
      </joint>
      <joint name="rear_left_wheel_joint">
          <command_interface name="velocity"/>
          <state_interface name="velocity"/>
      </joint>
      <joint name="rear_right_wheel_joint">
          <command_interface name="velocity"/>
          <state_interface name="velocity"/>
      </joint>
  </ros2_control>
</robot>